[2025-01-30T12:08:08.602+0000] {local_task_job_runner.py:123} INFO - ::group::Pre task execution logs
[2025-01-30T12:08:08.806+0000] {taskinstance.py:2612} INFO - Dependencies all met for dep_context=non-requeueable deps ti=<TaskInstance: model_pipeline.run_predictions manual__2025-01-30T12:06:57.646766+00:00 [queued]>
[2025-01-30T12:08:09.404+0000] {taskinstance.py:2612} INFO - Dependencies all met for dep_context=requeueable deps ti=<TaskInstance: model_pipeline.run_predictions manual__2025-01-30T12:06:57.646766+00:00 [queued]>
[2025-01-30T12:08:09.617+0000] {taskinstance.py:2865} INFO - Starting attempt 1 of 2
[2025-01-30T12:08:09.635+0000] {taskinstance.py:2888} INFO - Executing <Task(PythonOperator): run_predictions> on 2025-01-30 12:06:57.646766+00:00
[2025-01-30T12:08:09.646+0000] {warnings.py:112} WARNING - /home/***/.local/lib/python3.12/site-packages/***/task/task_runner/standard_task_runner.py:70: DeprecationWarning: This process (pid=104) is multi-threaded, use of fork() may lead to deadlocks in the child.
  pid = os.fork()

[2025-01-30T12:08:09.648+0000] {standard_task_runner.py:104} INFO - Running: ['***', 'tasks', 'run', 'model_pipeline', 'run_predictions', 'manual__2025-01-30T12:06:57.646766+00:00', '--job-id', '42', '--raw', '--subdir', 'DAGS_FOLDER/hw_dag.py', '--cfg-path', '/tmp/tmpgyfc4poq']
[2025-01-30T12:08:09.649+0000] {standard_task_runner.py:72} INFO - Started process 121 to run task
[2025-01-30T12:08:09.649+0000] {standard_task_runner.py:105} INFO - Job 42: Subtask run_predictions
[2025-01-30T12:08:09.701+0000] {task_command.py:467} INFO - Running <TaskInstance: model_pipeline.run_predictions manual__2025-01-30T12:06:57.646766+00:00 [running]> on host 13fa6b44c1bf
[2025-01-30T12:08:09.793+0000] {taskinstance.py:3131} INFO - Exporting env vars: AIRFLOW_CTX_DAG_OWNER='***' AIRFLOW_CTX_DAG_ID='model_pipeline' AIRFLOW_CTX_TASK_ID='run_predictions' AIRFLOW_CTX_EXECUTION_DATE='2025-01-30T12:06:57.646766+00:00' AIRFLOW_CTX_TRY_NUMBER='1' AIRFLOW_CTX_DAG_RUN_ID='manual__2025-01-30T12:06:57.646766+00:00'
[2025-01-30T12:08:09.795+0000] {logging_mixin.py:190} INFO - Task instance is in running state
[2025-01-30T12:08:09.795+0000] {logging_mixin.py:190} INFO -  Previous state of the Task instance: queued
[2025-01-30T12:08:09.796+0000] {logging_mixin.py:190} INFO - Current task name:run_predictions state:running start_date:2025-01-30 12:08:09.381016+00:00
[2025-01-30T12:08:09.796+0000] {logging_mixin.py:190} INFO - Dag name:model_pipeline and current dag run status:running
[2025-01-30T12:08:09.797+0000] {taskinstance.py:731} INFO - ::endgroup::
[2025-01-30T12:08:09.805+0000] {warnings.py:112} WARNING - /home/***/.local/lib/python3.12/site-packages/sklearn/base.py:380: InconsistentVersionWarning: Trying to unpickle estimator FunctionTransformer from version 1.5.1 when using version 1.6.1. This might lead to breaking code or invalid results. Use at your own risk. For more info please refer to:
https://scikit-learn.org/stable/model_persistence.html#security-maintainability-limitations
  warnings.warn(

[2025-01-30T12:08:09.806+0000] {warnings.py:112} WARNING - /home/***/.local/lib/python3.12/site-packages/sklearn/base.py:380: InconsistentVersionWarning: Trying to unpickle estimator SimpleImputer from version 1.5.1 when using version 1.6.1. This might lead to breaking code or invalid results. Use at your own risk. For more info please refer to:
https://scikit-learn.org/stable/model_persistence.html#security-maintainability-limitations
  warnings.warn(

[2025-01-30T12:08:09.807+0000] {warnings.py:112} WARNING - /home/***/.local/lib/python3.12/site-packages/sklearn/base.py:380: InconsistentVersionWarning: Trying to unpickle estimator StandardScaler from version 1.5.1 when using version 1.6.1. This might lead to breaking code or invalid results. Use at your own risk. For more info please refer to:
https://scikit-learn.org/stable/model_persistence.html#security-maintainability-limitations
  warnings.warn(

[2025-01-30T12:08:09.807+0000] {warnings.py:112} WARNING - /home/***/.local/lib/python3.12/site-packages/sklearn/base.py:380: InconsistentVersionWarning: Trying to unpickle estimator Pipeline from version 1.5.1 when using version 1.6.1. This might lead to breaking code or invalid results. Use at your own risk. For more info please refer to:
https://scikit-learn.org/stable/model_persistence.html#security-maintainability-limitations
  warnings.warn(

[2025-01-30T12:08:09.808+0000] {warnings.py:112} WARNING - /home/***/.local/lib/python3.12/site-packages/sklearn/base.py:380: InconsistentVersionWarning: Trying to unpickle estimator OneHotEncoder from version 1.5.1 when using version 1.6.1. This might lead to breaking code or invalid results. Use at your own risk. For more info please refer to:
https://scikit-learn.org/stable/model_persistence.html#security-maintainability-limitations
  warnings.warn(

[2025-01-30T12:08:09.814+0000] {warnings.py:112} WARNING - /home/***/.local/lib/python3.12/site-packages/sklearn/base.py:380: InconsistentVersionWarning: Trying to unpickle estimator ColumnTransformer from version 1.5.1 when using version 1.6.1. This might lead to breaking code or invalid results. Use at your own risk. For more info please refer to:
https://scikit-learn.org/stable/model_persistence.html#security-maintainability-limitations
  warnings.warn(

[2025-01-30T12:08:09.824+0000] {warnings.py:112} WARNING - /home/***/.local/lib/python3.12/site-packages/sklearn/base.py:380: InconsistentVersionWarning: Trying to unpickle estimator SVC from version 1.5.1 when using version 1.6.1. This might lead to breaking code or invalid results. Use at your own risk. For more info please refer to:
https://scikit-learn.org/stable/model_persistence.html#security-maintainability-limitations
  warnings.warn(

[2025-01-30T12:08:09.833+0000] {predict.py:56} ERROR - Ошибка при предсказании для файла 7310993818.json: list indices must be integers or slices, not DataFrame
[2025-01-30T12:08:09.837+0000] {predict.py:56} ERROR - Ошибка при предсказании для файла 7313922964.json: list indices must be integers or slices, not DataFrame
[2025-01-30T12:08:09.839+0000] {predict.py:56} ERROR - Ошибка при предсказании для файла 7315173150.json: list indices must be integers or slices, not DataFrame
[2025-01-30T12:08:09.851+0000] {predict.py:56} ERROR - Ошибка при предсказании для файла 7316152972.json: list indices must be integers or slices, not DataFrame
[2025-01-30T12:08:09.857+0000] {predict.py:56} ERROR - Ошибка при предсказании для файла 7316509996.json: list indices must be integers or slices, not DataFrame
[2025-01-30T12:08:09.858+0000] {taskinstance.py:3310} ERROR - Task failed with exception
Traceback (most recent call last):
  File "/home/airflow/.local/lib/python3.12/site-packages/airflow/models/taskinstance.py", line 767, in _execute_task
    result = _execute_callable(context=context, **execute_callable_kwargs)
             ^^^^^^^^^^^^^^^^^^^^^^^^^^^^^^^^^^^^^^^^^^^^^^^^^^^^^^^^^^^^^
  File "/home/airflow/.local/lib/python3.12/site-packages/airflow/models/taskinstance.py", line 733, in _execute_callable
    return ExecutionCallableRunner(
           ^^^^^^^^^^^^^^^^^^^^^^^^
  File "/home/airflow/.local/lib/python3.12/site-packages/airflow/utils/operator_helpers.py", line 252, in run
    return self.func(*args, **kwargs)
           ^^^^^^^^^^^^^^^^^^^^^^^^^^
  File "/home/airflow/.local/lib/python3.12/site-packages/airflow/models/baseoperator.py", line 406, in wrapper
    return func(self, *args, **kwargs)
           ^^^^^^^^^^^^^^^^^^^^^^^^^^^
  File "/home/airflow/.local/lib/python3.12/site-packages/airflow/operators/python.py", line 238, in execute
    return_value = self.execute_callable()
                   ^^^^^^^^^^^^^^^^^^^^^^^
  File "/home/airflow/.local/lib/python3.12/site-packages/airflow/operators/python.py", line 256, in execute_callable
    return runner.run(*self.op_args, **self.op_kwargs)
           ^^^^^^^^^^^^^^^^^^^^^^^^^^^^^^^^^^^^^^^^^^^
  File "/home/airflow/.local/lib/python3.12/site-packages/airflow/utils/operator_helpers.py", line 252, in run
    return self.func(*args, **kwargs)
           ^^^^^^^^^^^^^^^^^^^^^^^^^^
  File "/opt/airflow/modules/predict.py", line 78, in predict
    predictions_df = make_predictions(model)
                     ^^^^^^^^^^^^^^^^^^^^^^^
  File "/opt/airflow/modules/predict.py", line 62, in make_predictions
    raise ValueError("Нет данных для предсказаний")
ValueError: Нет данных для предсказаний
[2025-01-30T12:08:09.875+0000] {logging_mixin.py:190} INFO - Task instance in failure state
[2025-01-30T12:08:09.876+0000] {logging_mixin.py:190} INFO - Task start:2025-01-30 12:08:09.381016+00:00 end:2025-01-30 12:08:09.874747+00:00 duration:0.493731
[2025-01-30T12:08:09.876+0000] {logging_mixin.py:190} INFO - Task:<Task(PythonOperator): run_predictions> dag:<DAG: model_pipeline> dagrun:<DagRun model_pipeline @ 2025-01-30 12:06:57.646766+00:00: manual__2025-01-30T12:06:57.646766+00:00, state:running, queued_at: 2025-01-30 12:06:57.670080+00:00. externally triggered: True>
[2025-01-30T12:08:09.877+0000] {logging_mixin.py:190} INFO - Failure caused by Нет данных для предсказаний
[2025-01-30T12:08:09.878+0000] {taskinstance.py:1225} INFO - Marking task as UP_FOR_RETRY. dag_id=model_pipeline, task_id=run_predictions, run_id=manual__2025-01-30T12:06:57.646766+00:00, execution_date=20250130T120657, start_date=20250130T120809, end_date=20250130T120809
[2025-01-30T12:08:09.899+0000] {taskinstance.py:340} INFO - ::group::Post task execution logs
[2025-01-30T12:08:10.083+0000] {standard_task_runner.py:124} ERROR - Failed to execute job 42 for task run_predictions (Нет данных для предсказаний; 121)
Traceback (most recent call last):
  File "/home/airflow/.local/lib/python3.12/site-packages/airflow/task/task_runner/standard_task_runner.py", line 117, in _start_by_fork
    ret = args.func(args, dag=self.dag)
          ^^^^^^^^^^^^^^^^^^^^^^^^^^^^^
  File "/home/airflow/.local/lib/python3.12/site-packages/airflow/cli/cli_config.py", line 49, in command
    return func(*args, **kwargs)
           ^^^^^^^^^^^^^^^^^^^^^
  File "/home/airflow/.local/lib/python3.12/site-packages/airflow/utils/cli.py", line 115, in wrapper
    return f(*args, **kwargs)
           ^^^^^^^^^^^^^^^^^^
  File "/home/airflow/.local/lib/python3.12/site-packages/airflow/cli/commands/task_command.py", line 483, in task_run
    task_return_code = _run_task_by_selected_method(args, _dag, ti)
                       ^^^^^^^^^^^^^^^^^^^^^^^^^^^^^^^^^^^^^^^^^^^^
  File "/home/airflow/.local/lib/python3.12/site-packages/airflow/cli/commands/task_command.py", line 256, in _run_task_by_selected_method
    return _run_raw_task(args, ti)
           ^^^^^^^^^^^^^^^^^^^^^^^
  File "/home/airflow/.local/lib/python3.12/site-packages/airflow/cli/commands/task_command.py", line 341, in _run_raw_task
    return ti._run_raw_task(
           ^^^^^^^^^^^^^^^^^
  File "/home/airflow/.local/lib/python3.12/site-packages/airflow/utils/session.py", line 97, in wrapper
    return func(*args, session=session, **kwargs)
           ^^^^^^^^^^^^^^^^^^^^^^^^^^^^^^^^^^^^^^
  File "/home/airflow/.local/lib/python3.12/site-packages/airflow/models/taskinstance.py", line 3004, in _run_raw_task
    return _run_raw_task(
           ^^^^^^^^^^^^^^
  File "/home/airflow/.local/lib/python3.12/site-packages/airflow/models/taskinstance.py", line 273, in _run_raw_task
    TaskInstance._execute_task_with_callbacks(
  File "/home/airflow/.local/lib/python3.12/site-packages/airflow/models/taskinstance.py", line 3158, in _execute_task_with_callbacks
    result = self._execute_task(context, task_orig)
             ^^^^^^^^^^^^^^^^^^^^^^^^^^^^^^^^^^^^^^
  File "/home/airflow/.local/lib/python3.12/site-packages/airflow/models/taskinstance.py", line 3182, in _execute_task
    return _execute_task(self, context, task_orig)
           ^^^^^^^^^^^^^^^^^^^^^^^^^^^^^^^^^^^^^^^
  File "/home/airflow/.local/lib/python3.12/site-packages/airflow/models/taskinstance.py", line 767, in _execute_task
    result = _execute_callable(context=context, **execute_callable_kwargs)
             ^^^^^^^^^^^^^^^^^^^^^^^^^^^^^^^^^^^^^^^^^^^^^^^^^^^^^^^^^^^^^
  File "/home/airflow/.local/lib/python3.12/site-packages/airflow/models/taskinstance.py", line 733, in _execute_callable
    return ExecutionCallableRunner(
           ^^^^^^^^^^^^^^^^^^^^^^^^
  File "/home/airflow/.local/lib/python3.12/site-packages/airflow/utils/operator_helpers.py", line 252, in run
    return self.func(*args, **kwargs)
           ^^^^^^^^^^^^^^^^^^^^^^^^^^
  File "/home/airflow/.local/lib/python3.12/site-packages/airflow/models/baseoperator.py", line 406, in wrapper
    return func(self, *args, **kwargs)
           ^^^^^^^^^^^^^^^^^^^^^^^^^^^
  File "/home/airflow/.local/lib/python3.12/site-packages/airflow/operators/python.py", line 238, in execute
    return_value = self.execute_callable()
                   ^^^^^^^^^^^^^^^^^^^^^^^
  File "/home/airflow/.local/lib/python3.12/site-packages/airflow/operators/python.py", line 256, in execute_callable
    return runner.run(*self.op_args, **self.op_kwargs)
           ^^^^^^^^^^^^^^^^^^^^^^^^^^^^^^^^^^^^^^^^^^^
  File "/home/airflow/.local/lib/python3.12/site-packages/airflow/utils/operator_helpers.py", line 252, in run
    return self.func(*args, **kwargs)
           ^^^^^^^^^^^^^^^^^^^^^^^^^^
  File "/opt/airflow/modules/predict.py", line 78, in predict
    predictions_df = make_predictions(model)
                     ^^^^^^^^^^^^^^^^^^^^^^^
  File "/opt/airflow/modules/predict.py", line 62, in make_predictions
    raise ValueError("Нет данных для предсказаний")
ValueError: Нет данных для предсказаний
[2025-01-30T12:08:10.509+0000] {local_task_job_runner.py:266} INFO - Task exited with return code 1
[2025-01-30T12:08:10.613+0000] {taskinstance.py:3900} INFO - 0 downstream tasks scheduled from follow-on schedule check
[2025-01-30T12:08:10.677+0000] {local_task_job_runner.py:245} INFO - ::endgroup::
